Workbook

Sheet Marco Lógico
B2: Marco Lógico
B5: Nombre del proyecto | C5: ConEsperanza
B6: Fecha inicio | C6: 46157 | D6: Fecha fin | H6: 46341
B7: Responsable | C7: CARE | D7: Socio | H7: NA
B8: Total participantes directos | C8: 28632 (23.251 ÚNICOS)
B9: Territorios | C9: Cauca (Buenos Aires y Morales) , Norte de Santander (Ocaña, Abrego, Harací, Teorama, La Playa de Belén, Convención)
B10: Presupuesto | C10: 2261471 USD
B12: Objetivo General | C12: Indicadores | D12: Metas | F12: Responsable | G12: Notas | H12: Medios de verificación
B13: Respuesta de emergencia para salvar vidas dirigida a comunidades que se enfrentan graves necesidades humanitarias en municipios prioritarios de Colombia. | C13: % de participantes que afirman que la ayuda humanitaria se presta de manera segura, accesible, responsable y participativa | D13: 0.8 | F13: CARE | H13: Encuestas de Satisfacción y PDM
B14: Actividades /productos | C14: Indicadores | D14: Metas doble conteo | E14: Metas únicos | F14: Responsable | G14: Notas | H14: Medios de verificación
B15: 1. Protección
B16: 1.1 Sensibilización comunitaria, difusión de información y campañas de comunicación sobre los mecanismos de protección disponibles para la población destinataria, para la prevención de riesgos de protección, la violanción de los derechos y la prevención de la violencia basada en género. Actividad estándar OCHA: C-CA19. ACTIVITY. Establishment of protection and prevention mechanisms by identifying high-risk areas and risk factors driving violence against women and girls in the emergency. Strengthen or set up prevention and mitigation strategies, mechanisms and initiatives in support of national and community-based interventions in line with IASC principles and guidelines. Risk mitigation strategies may include the provision of dignity kits and other means of sharing life-saving protection information. | C16: C-CA19. INDICATOR 74: Number of individuals who received life‑saving protection support through newly established or strengthened violence prevention and risk‑mitigation mechanisms. | D16: 8000 | E16: 8000 | F16: CARE | H16: 1. Listados de Asistencia 2. Actas de actividad (espacios masivos) 3. Registro en CommCare 4. BBDD sistema de monitoreo CARE COL 5. Archivo seguimiento eventos masivos
B17: 1.2 Gestión de casos para personas víctimas de conflicto armado, en situación de riesgo o sobrevivientes de violencia de género, incluyendo derivaciones internas y externas Actividad estándar OCHA: C-CA11. ACTIVITY: Provision of life-saving support to people with specific needs, survivors of violence against women and girls and/or sexual exploitation and abuse. This includes strengthening psychosocial support (PSS) programming and non- specialized Mental Health and Psychosocial Support Services (MHPSS) to individuals, families, and communities that have been exposed to conflict and displacement, political oppression, torture, and violence against women and girls; and support in promoting community mobilization, activating social networks, and the establishment of community centers and safe spaces. | C17: C-CA11. INDICATOR 65. Number of people receiving violence psycho-social support and/or violence case management | D17: 1152 | E17: 0 | F17: CARE | H17: 1. Registro de todo el ciclo de la Gestión de Caso en el sistema de monitoreo de CARE COL 2. BBDD sistema de monitoreo CARE COL
B18: 1.3 Entrega de cash a personas en situación de riesgo o sobrevivientes de violencia de género priorizadas en el proceso de gestión de casos Actividad estándar OCHA: C-CA16. ACTIVITY. Provision of financial, cash or voucher / CVA assistance for protection outcomes | C18: C-CA16. INDICATOR. Number of people affected benefiting from emergency cash assistance or direct service payments | D18: 403 | E18: 0 | F18: CARE | H18: 1. Registro entrega de priorización y entrega de cash en el sistema de monitoreo 2. Tirillas de entrega del cash - proveedor de servicios financieros (ventanilla) /BBDD proveedor 3. BBDD sistema de monitoreo CARE COL 4. BBDD seguimiento coordinación PTM
B19: 1.4 Entrega de kits - CARE Package- Actividad estándar OCHA: C-CA19. ACTIVITY. Establishment of protection and prevention mechanisms by identifying high-risk areas and risk factors driving violence against women and girls in the emergency. Strengthen or set up prevention and mitigation strategies, mechanisms and initiatives in support of national and community-based interventions in line with IASC principles and guidelines. Risk mitigation strategies may include the provision of dignity kits and other means of sharing life-saving protection information. | C19: C-CA19. INDICATOR 74: Number of individuals who received life‑saving protection support through newly established or strengthened violence prevention and risk‑mitigation mechanisms. | D19: 9600 | E19: 7200 | F19: CARE | G19: *Son 2400 kits entregados a hogares (x 4 miembros) | H19: 1. Registro entrega de kits en el sistema de monitoreo 2. Listados de distribución de kits 2. BBDD sistema de monitoreo CARE COL
B20: 1.5 Fortalecimiento protección en espacios seguros, gestionados por organizaciones de base, institucionalidad del gobierno y organismos homólogos. Actividad estándar OCHA: C-CA11. ACTIVITY: Provision of life-saving support to people with specific needs, survivors of violence against women and girls and/or sexual exploitation and abuse. This includes strengthening psychosocial support (PSS) programming and non- specialized Mental Health and Psychosocial Support Services (MHPSS) to individuals, families, and communities that have been exposed to conflict and displacement, political oppression, torture, and violence against women and girls; and support in promoting community mobilization, activating social networks, and the establishment of community centers and safe spaces. | C20: C-CA11. INDICATOR 65. Number of people receiving violence psycho-social support and/or violence case management | D20: 5400 | E20: 5400 | F20: CARE | H20: 1. Mapeo y diagnóstico 2. Plan de trabajo 3. Acta de entrega (dotación - mejoras) 4. Actas de seguimiento 5. Archivo consolidado de seguimiento
B21: 2. Salud
B22: 2.1 Prestación de servicios de atención primaria de salud Actividad estándar OCHA: C-CA1: ACTIVITY. Ensuring equitable and timely access to emergency primary healthcare, including the link with community health systems and outreach activities. | C22: C-CA1. INDICATOR 28: Number of primary healthcare consultations provided | D22: 1345 | E22: 1211 | F22: CARE | G22: *2.690 consultas (en promedio dos por persona) | H22: 1. Voucher de salud en el sistema de monitoreo 2. BBDD sistema de monitoreo CARE COL 3. BBDD proveedor de servicios
B23: 2.2 Entre kits postparto Actividad estándar OCHA: C-CA1: ACTIVITY. Ensuring equitable and timely access to emergency primary healthcare, including the link with community health systems and outreach activities. | C23: C-CA1. INDICATOR 28: Number of primary healthcare consultations provided | D23: 140 | E23: 0 | F23: CARE | H23: 1. Registro entrega de kits en el sistema de monitoreo 2. Listados de distribución de kits 2. BBDD sistema de monitoreo CARE COL
B24: 2.3 Prestación de servicios de atención medica a las personas sobrevientes de violencia sexual Actividad estándar OCHA: C-CA11: ACTIVITY. Medical (including psychological) support to survivors of sexual violence and other forms of violence against women and girls. This can include Mental Health and Psychosocial Support (MHPSS), refresher training for frontline health staff on clinical management of rape and intimate partner violence (IPV), and supply of drugs, material and equipment including through interagency reproductive health kits. | C24: C-CA11. INDICATOR 43: Number of violence survivors receiving medical assistance, including clinical management of rape | D24: 576 | E24: 0 | F24: CARE | H24: 1. Voucher de salud en el sistema de monitoreo 2. BBDD sistema de monitoreo CARE COL 3. BBDD proveedor de servicios
B25: 3. Cash multipropósito
B26: 3.1 Cash Multipropósito Actividad estándar OCHA: C-CA1. ACTIVITY: Provision of multi purpose cash | C26: C-CA1. INDICATOR 117: Number of households having received Multi-Purpose Cash (MPC) | D26: 2016 | E26: 1440 | F26: CARE | G26: *576 hogares (x 3.5 miembros) | H26: 1. Registro en CommCare 2. BBDD entrega Cash 3. Tirillas entrega del proveedor de serivicio / BBDD proveedor 4. BBDD seguimiento coordinación PTM
B27: Total participantes directos | D27: =D16+D17+D18+D19+D20+D22+D23+D24+D26 -> 28632 | E27: =E16+E17+E18+E19+E20+E22+E23+E24+E26 -> 23251

Sheet Detalle metas
A1: Sector | B1: Actividad | C1: Meta total | D1: Cauca | E1: Buenos Aires | F1: May | G1: Jun | H1: Jul | I1: Ago | J1: Sep | K1: Oct | L1: Nov | M1: Morales | N1: May | O1: Jun | P1: Jul | Q1: Ago | R1: Sep | S1: Oct | T1: Nov | U1: Norte de Santander | V1: Abrego | W1: May | X1: Jun | Y1: Jul | Z1: Ago | AA1: Sep | AB1: Oct | AC1: Nov | AD1: Ocaña | AE1: May | AF1: Jun | AG1: Jul | AH1: Ago | AI1: Sep | AJ1: Oct | AK1: Nov | AL1: Convención | AM1: May | AN1: Jun | AO1: Jul | AP1: Ago | AQ1: Sep | AR1: Oct | AS1: Nov | AT1: Teorama | AU1: May | AV1: Jun | AW1: Jul | AX1: Ago | AY1: Sep | AZ1: Oct | BA1: Nov | BB1: Hacarí | BC1: May | BD1: Jun | BE1: Jul | BF1: Ago | BG1: Sep | BH1: Oct | BI1: Nov | BJ1: La Playa de Belén | BK1: May | BL1: Jun | BM1: Jul | BN1: Ago | BO1: Sep | BP1: Oct | BQ1: Nov
A2: Protección | B2: Sensibilizaciones general (10%) | C2: 1600 | D2: =E2+M2 -> 480 | E2: =F2+G2+H2+I2+J2+K2+L2 -> 240 | F2: 0 | G2: 24 | H2: 54 | I2: 54 | J2: 54 | K2: 54 | L2: 0 | M2: =N2+O2+P2+Q2+R2+S2+T2 -> 240 | N2: 0 | O2: 24 | P2: 54 | Q2: 54 | R2: 54 | S2: 54 | T2: 0 | U2: =V2+AD2+AL2+AT2+BB2+BJ2 -> 1120 | V2: =W2+X2+Y2+Z2+AA2+AB2+AC2 -> 240 | W2: 0 | X2: 24 | Y2: 54 | Z2: 54 | AA2: 54 | AB2: 54 | AC2: 0 | AD2: =AE2+AF2+AG2+AH2+AI2+AJ2+AK2 -> 240 | AE2: 0 | AF2: 24 | AG2: 54 | AH2: 54 | AI2: 54 | AJ2: 54 | AK2: 0 | AL2: =AM2+AN2+AO2+AP2+AQ2+AR2+AS2 -> 160 | AM2: 0 | AN2: 16 | AO2: 36 | AP2: 36 | AQ2: 36 | AR2: 36 | AS2: 0 | AT2: =AU2+AV2+AW2+AX2+AY2+AZ2+BA2 -> 160 | AU2: 0 | AV2: 16 | AW2: 36 | AX2: 36 | AY2: 36 | AZ2: 36 | BA2: 0 | BB2: =BC2+BD2+BE2+BF2+BG2+BH2+BI2 -> 160 | BC2: 0 | BD2: 16 | BE2: 36 | BF2: 36 | BG2: 36 | BH2: 36 | BI2: 0 | BJ2: =BK2+BL2+BM2+BN2+BO2+BP2+BQ2 -> 160 | BK2: 0 | BL2: 16 | BM2: 36 | BN2: 36 | BO2: 36 | BP2: 36 | BQ2: 0
A3: Protección | B3: Sensibilizaciones VBG (80%) | C3: 6400 | D3: =E3+M3 -> 1920 | E3: =F3+G3+H3+I3+J3+K3+L3 -> 960 | F3: 0 | G3: 96 | H3: 216 | I3: 216 | J3: 216 | K3: 216 | L3: 0 | M3: =N3+O3+P3+Q3+R3+S3+T3 -> 960 | N3: 0 | O3: 96 | P3: 216 | Q3: 216 | R3: 216 | S3: 216 | T3: 0 | U3: =V3+AD3+AL3+AT3+BB3+BJ3 -> 4480 | V3: =W3+X3+Y3+Z3+AA3+AB3+AC3 -> 960 | W3: 0 | X3: 96 | Y3: 216 | Z3: 216 | AA3: 216 | AB3: 216 | AC3: 0 | AD3: =AE3+AF3+AG3+AH3+AI3+AJ3+AK3 -> 960 | AE3: 0 | AF3: 96 | AG3: 216 | AH3: 216 | AI3: 216 | AJ3: 216 | AK3: 0 | AL3: =AM3+AN3+AO3+AP3+AQ3+AR3+AS3 -> 640 | AM3: 0 | AN3: 64 | AO3: 144 | AP3: 144 | AQ3: 144 | AR3: 144 | AS3: 0 | AT3: =AU3+AV3+AW3+AX3+AY3+AZ3+BA3 -> 640 | AU3: 0 | AV3: 64 | AW3: 144 | AX3: 144 | AY3: 144 | AZ3: 144 | BA3: 0 | BB3: =BC3+BD3+BE3+BF3+BG3+BH3+BI3 -> 640 | BC3: 0 | BD3: 64 | BE3: 144 | BF3: 144 | BG3: 144 | BH3: 144 | BI3: 0 | BJ3: =BK3+BL3+BM3+BN3+BO3+BP3+BQ3 -> 640 | BK3: 0 | BL3: 64 | BM3: 144 | BN3: 144 | BO3: 144 | BP3: 144 | BQ3: 0
A4: Protección | B4: Gestión de Casos | C4: 1152 | D4: =E4+M4 -> 576 | E4: =F4+G4+H4+I4+J4+K4+L4 -> 288 | F4: 0 | G4: 48 | H4: 60 | I4: 60 | J4: 60 | K4: 60 | L4: 0 | M4: =N4+O4+P4+Q4+R4+S4+T4 -> 288 | N4: 0 | O4: 48 | P4: 60 | Q4: 60 | R4: 60 | S4: 60 | T4: 0 | U4: =V4+AD4+AL4+AT4+BB4+BJ4 -> 576 | V4: =W4+X4+Y4+Z4+AA4+AB4+AC4 -> 96 | W4: 0 | X4: 16 | Y4: 20 | Z4: 20 | AA4: 20 | AB4: 20 | AC4: 0 | AD4: =AE4+AF4+AG4+AH4+AI4+AJ4+AK4 -> 96 | AE4: 0 | AF4: 16 | AG4: 20 | AH4: 20 | AI4: 20 | AJ4: 20 | AK4: 0 | AL4: =AM4+AN4+AO4+AP4+AQ4+AR4+AS4 -> 96 | AM4: 0 | AN4: 16 | AO4: 20 | AP4: 20 | AQ4: 20 | AR4: 20 | AS4: 0 | AT4: =AU4+AV4+AW4+AX4+AY4+AZ4+BA4 -> 96 | AU4: 0 | AV4: 16 | AW4: 20 | AX4: 20 | AY4: 20 | AZ4: 20 | BA4: 0 | BB4: =BC4+BD4+BE4+BF4+BG4+BH4+BI4 -> 96 | BC4: 0 | BD4: 16 | BE4: 20 | BF4: 20 | BG4: 20 | BH4: 20 | BI4: 0 | BJ4: =BK4+BL4+BM4+BN4+BO4+BP4+BQ4 -> 96 | BK4: 0 | BL4: 16 | BM4: 20 | BN4: 20 | BO4: 20 | BP4: 20 | BQ4: 0
A5: Protección | B5: Cash VBG | C5: 403 | D5: =E5+M5 -> 230 | E5: =F5+G5+H5+I5+J5+K5+L5 -> 115 | F5: 0 | G5: 15 | H5: 25 | I5: 25 | J5: 25 | K5: 25 | L5: 0 | M5: =N5+O5+P5+Q5+R5+S5+T5 -> 115 | N5: 0 | O5: 15 | P5: 25 | Q5: 25 | R5: 25 | S5: 25 | T5: 0 | U5: =V5+AD5+AL5+AT5+BB5+BJ5 -> 173 | V5: =W5+X5+Y5+Z5+AA5+AB5+AC5 -> 29 | W5: 0 | X5: 3 | Y5: 7 | Z5: 7 | AA5: 7 | AB5: 5 | AC5: 0 | AD5: =AE5+AF5+AG5+AH5+AI5+AJ5+AK5 -> 29 | AE5: 0 | AF5: 3 | AG5: 7 | AH5: 7 | AI5: 7 | AJ5: 5 | AK5: 0 | AL5: =AM5+AN5+AO5+AP5+AQ5+AR5+AS5 -> 29 | AM5: 0 | AN5: 3 | AO5: 7 | AP5: 7 | AQ5: 7 | AR5: 5 | AS5: 0 | AT5: =AU5+AV5+AW5+AX5+AY5+AZ5+BA5 -> 28 | AU5: 0 | AV5: 3 | AW5: 7 | AX5: 7 | AY5: 7 | AZ5: 4 | BA5: 0 | BB5: =BC5+BD5+BE5+BF5+BG5+BH5+BI5 -> 29 | BC5: 0 | BD5: 3 | BE5: 7 | BF5: 7 | BG5: 7 | BH5: 5 | BI5: 0 | BJ5: =BK5+BL5+BM5+BN5+BO5+BP5+BQ5 -> 29 | BK5: 0 | BL5: 3 | BM5: 7 | BN5: 7 | BO5: 7 | BP5: 5 | BQ5: 0
A6: Protección | B6: Kits - CARE Package- (meta hogar) | C6: 2400 | D6: =E6+M6 -> 600 | E6: =F6+G6+H6+I6+J6+K6+L6 -> 300 | F6: 0 | G6: 30 | H6: 60 | I6: 75 | J6: 75 | K6: 60 | L6: 0 | M6: =N6+O6+P6+Q6+R6+S6+T6 -> 300 | N6: 0 | O6: 30 | P6: 60 | Q6: 75 | R6: 75 | S6: 60 | T6: 0 | U6: =V6+AD6+AL6+AT6+BB6+BJ6 -> 1800 | V6: =W6+X6+Y6+Z6+AA6+AB6+AC6 -> 300 | W6: 0 | X6: 30 | Y6: 60 | Z6: 75 | AA6: 75 | AB6: 60 | AC6: 0 | AD6: =AE6+AF6+AG6+AH6+AI6+AJ6+AK6 -> 300 | AE6: 0 | AF6: 30 | AG6: 60 | AH6: 75 | AI6: 75 | AJ6: 60 | AK6: 0 | AL6: =AM6+AN6+AO6+AP6+AQ6+AR6+AS6 -> 300 | AM6: 0 | AN6: 30 | AO6: 60 | AP6: 75 | AQ6: 75 | AR6: 60 | AS6: 0 | AT6: =AU6+AV6+AW6+AX6+AY6+AZ6+BA6 -> 300 | AU6: 0 | AV6: 30 | AW6: 60 | AX6: 75 | AY6: 75 | AZ6: 60 | BA6: 0 | BB6: =BC6+BD6+BE6+BF6+BG6+BH6+BI6 -> 300 | BC6: 0 | BD6: 30 | BE6: 60 | BF6: 75 | BG6: 75 | BH6: 60 | BI6: 0 | BJ6: =BK6+BL6+BM6+BN6+BO6+BP6+BQ6 -> 300 | BK6: 0 | BL6: 30 | BM6: 60 | BN6: 75 | BO6: 75 | BP6: 60 | BQ6: 0
A7: Protección | B7: Kits - CARE Package- (meta personas) | C7: =C6*4 -> 9600 | D7: =D6*4 -> 2400 | E7: =E6*4 -> 1200 | F7: =F6*$A$17 -> 0 | G7: =G6*$A$17 -> 120 | H7: =H6*$A$17 -> 240 | I7: =I6*$A$17 -> 300 | J7: =J6*$A$17 -> 300 | K7: =K6*$A$17 -> 240 | L7: =L6*$A$17 -> 0 | M7: =M6*$A$17 -> 1200 | ... BQ7: =BQ6*$A$17 -> 0
A8: Protección | B8: Espacios seguros mejorados | C8: 8 | D8: 2 | E8: 1 | F8: 0 | G8: 0 | H8: 0 | I8: 1 | J8: 0 | K8: 0 | L8: 0 | M8: 1 | N8: 0 | O8: 0 | P8: 0 | Q8: 1 | R8: 0 | S8: 0 | T8: 0 | U8: 6 | V8: 1 | W8: 0 | X8: 0 | Y8: 0 | Z8: 1 | AA8: 0 | AB8: 0 | AC8: 0 | AD8: 1 | AE8: 0 | AF8: 0 | AG8: 0 | AH8: 1 | AI8: 0 | AJ8: 0 | AK8: 0 | AL8: 1 | AM8: 0 | AN8: 0 | AO8: 0 | AP8: 1 | AQ8: 0 | AR8: 0 | AS8: 0 | AT8: 1 | AU8: 0 | AV8: 0 | AW8: 0 | AX8: 1 | AY8: 0 | AZ8: 0 | BA8: 0 | BB8: 1 | BC8: 0 | BD8: 0 | BE8: 0 | BF8: 1 | BG8: 0 | BH8: 0 | BI8: 0 | BJ8: 1 | BK8: 0 | BL8: 0 | BM8: 0 | BN8: 1 | BO8: 0 | BP8: 0 | BQ8: 0
A9: Protección | B9: Espacios seguros participantes | C9: =D9+U9 -> 5400 | D9: =E9+M9 -> 1800 | E9: =F9+G9+H9+I9+J9+K9+L9 -> 900 | F9: 0 | G9: 0 | H9: 0 | I9: 180 | J9: 360 | K9: 360 | L9: 0 | M9: =N9+O9+P9+Q9+R9+S9+T9 -> 900 | N9: 0 | O9: 0 | P9: 0 | Q9: 180 | R9: 360 | S9: 360 | T9: 0 | U9: =V9+AD9+AL9+AT9+BB9+BJ9 -> 3600 | V9: =W9+X9+Y9+Z9+AA9+AB9+AC9 -> 900 | W9: 0 | X9: 0 | Y9: 0 | Z9: 180 | AA9: 360 | AB9: 360 | AC9: 0 | AD9: =AE9+AF9+AG9+AH9+AI9+AJ9+AK9 -> 900 | AE9: 0 | AF9: 0 | AG9: 0 | AH9: 180 | AI9: 360 | AJ9: 360 | AK9: 0 | AL9: =AM9+AN9+AO9+AP9+AQ9+AR9+AS9 -> 450 | AM9: 0 | AN9: 0 | AO9: 0 | AP9: 90 | AQ9: 180 | AR9: 180 | AS9: 0 | AT9: =AU9+AV9+AW9+AX9+AY9+AZ9+BA9 -> 450 | AU9: 0 | AV9: 0 | AW9: 0 | AX9: 90 | AY9: 180 | AZ9: 180 | BA9: 0 | BB9: =BC9+BD9+BE9+BF9+BG9+BH9+BI9 -> 450 | BC9: 0 | BD9: 0 | BE9: 0 | BF9: 90 | BG9: 180 | BH9: 180 | BI9: 0 | BJ9: =BK9+BL9+BM9+BN9+BO9+BP9+BQ9 -> 450 | BK9: 0 | BL9: 0 | BM9: 0 | BN9: 90 | BO9: 180 | BP9: 180 | BQ9: 0
A10: Salud | B10: Sensibilizaciones salud | C10: 1400 | D10: =E10+M10 -> 1400 | E10: =G10+H10+I10+J10+K10 -> 700 | F10: 0 | G10: 92 | H10: 161 | I10: 161 | J10: 161 | K10: 125 | L10: 0 | M10: =O10+P10+Q10+R10+S10 -> 700 | N10: 0 | O10: 92 | P10: 161 | Q10: 161 | R10: 161 | S10: 125 | T10: 0
A11: Salud | B11: Servicios salud primaria | C11: 2690 | D11: =E11+M11 -> 2690 | E11: =F11+G11+H11+I11+J11+K11+L11 -> 1345 | F11: 0 | G11: 144 | H11: 300 | I11: 300 | J11: 300 | K11: 301 | L11: 0 | M11: =N11+O11+P11+Q11+R11+S11+T11 -> 1345 | N11: 0 | O11: 144 | P11: 300 | Q11: 300 | R11: 300 | S11: 301 | T11: 0
A12: Salud | B12: Salud primaria personas únicas | C12: 1345 | D12: =E12+M12 -> 1345 | E12: =F12+G12+H12+I12+J12+K12+L12 -> 673 | F12: 0 | G12: 72 | H12: 150 | I12: 150 | J12: 150 | K12: 151 | L12: 0 | M12: =N12+O12+P12+Q12+R12+S12+T12 -> 672 | N12: 0 | O12: 72 | P12: 150 | Q12: 150 | R12: 150 | S12: 150 | T12: 0
A13: Salud | B13: Kits post - parto | C13: 140 | D13: =E13+M13 -> 140 | E13: =F13+G13+H13+I13+J13+K13+L13 -> 70 | F13: 0 | G13: 7 | H13: 16 | I13: 16 | J13: 16 | K13: 15 | L13: 0 | M13: =N13+O13+P13+Q13+R13+S13+T13 -> 70 | N13: 0 | O13: 7 | P13: 16 | Q13: 16 | R13: 16 | S13: 15 | T13: 0
A14: Salud | B14: Atención VBG | C14: 576 | D14: 576 | E14: =F14+G14+H14+I14+J14+K14+L14 -> 288 | F14: 0 | G14: 48 | H14: 60 | I14: 60 | J14: 60 | K14: 60 | L14: 0 | M14: =N14+O14+P14+Q14+R14+S14+T14 -> 288 | N14: 0 | O14: 48 | P14: 60 | Q14: 60 | R14: 60 | S14: 60 | T14: 0
A15: MPC | B15: Entrega cash multipropósito (meta hogar) | C15: 576 | D15: =E15+M15 -> 576 | E15: =F15+G15+H15+I15+J15+K15+L15 -> 288 | F15: 0 | G15: 30 | H15: 64 | I15: 66 | J15: 64 | K15: 64 | L15: 0 | M15: =N15+O15+P15+Q15+R15+S15+T15 -> 288 | N15: 0 | O15: 30 | P15: 64 | Q15: 66 | R15: 64 | S15: 64 | T15: 0
A16: MPC | B16: Entrega cash multipropósito (cantidad de entregas x 3) | C16: 1728 | D16: =E16+M16 -> 1728 | E16: =E15*3 -> 864 | F16: =F15*3 -> 0 | G16: =G15*3 -> 90 | H16: =H15*3 -> 192 | I16: =I15*3 -> 198 | J16: =J15*3 -> 192 | K16: =K15*3 -> 192 | L16: =L15*3 -> 0 | ... T16: =T15*3 -> 0
A17: 4
A19: Metas mensuales
A20: Sector | B20: Actividad | C20: Meta total | D20: May | E20: Jun | F20: Jul | G20: Ago | H20: Sep | I20: Oct | J20: Nov
A21: Protección | B21: Sensibilizaciones general (10%) | C21: 1600 | D21: =F2+N2+W2+AE2+AM2+AU2+BC2+BK2 -> 0 | E21: =G2+O2+X2+AF2+AN2+AV2+BD2+BL2 -> 160 | F21: =H2+P2+Y2+AG2+AO2+AW2+BE2+BM2 -> 360 | G21: =I2+Q2+Z2+AH2+AP2+AX2+BF2+BN2 -> 360 | H21: =J2+R2+AA2+AI2+AQ2+AY2+BG2+BO2 -> 360 | I21: =K2+S2+AB2+AJ2+AR2+AZ2+BH2+BP2 -> 360 | J21: =L2+T2+AC2+AK2+AS2+BA2+BI2+BQ2 -> 0
A22: Protección | B22: Sensibilizaciones VBG (80%) | C22: 6400 | D22: =F3+N3+W3+AE3+AM3+AU3+BC3+BK3 -> 0 | E22: =G3+O3+X3+AF3+AN3+AV3+BD3+BL3 -> 640 | F22: =H3+P3+Y3+AG3+AO3+AW3+BE3+BM3 -> 1440 | G22: =I3+Q3+Z3+AH3+AP3+AX3+BF3+BN3 -> 1440 | H22: =J3+R3+AA3+AI3+AQ3+AY3+BG3+BO3 -> 1440 | I22: =K3+S3+AB3+AJ3+AR3+AZ3+BH3+BP3 -> 1440 | J22: =L3+T3+AC3+AK3+AS3+BA3+BI3+BQ3 -> 0
A23: Protección | B23: Gestión de Casos | C23: 1152 | D23: =F4+N4+W4+AE4+AM4+AU4+BC4+BK4 -> 0 | E23: =G4+O4+X4+AF4+AN4+AV4+BD4+BL4 -> 192 | F23: =H4+P4+Y4+AG4+AO4+AW4+BE4+BM4 -> 240 | G23: =I4+Q4+Z4+AH4+AP4+AX4+BF4+BN4 -> 240 | H23: =J4+R4+AA4+AI4+AQ4+AY4+BG4+BO4 -> 240 | I23: =K4+S4+AB4+AJ4+AR4+AZ4+BH4+BP4 -> 240 | J23: =L4+T4+AC4+AK4+AS4+BA4+BI4+BQ4 -> 0
A24: Protección | B24: Cash VBG | C24: 403 | D24: =F5+N5+W5+AE5+AM5+AU5+BC5+BK5 -> 0 | E24: =G5+O5+X5+AF5+AN5+AV5+BD5+BL5 -> 48 | F24: =H5+P5+Y5+AG5+AO5+AW5+BE5+BM5 -> 92 | G24: =I5+Q5+Z5+AH5+AP5+AX5+BF5+BN5 -> 92 | H24: =J5+R5+AA5+AI5+AQ5+AY5+BG5+BO5 -> 92 | I24: =K5+S5+AB5+AJ5+AR5+AZ5+BH5+BP5 -> 79 | J24: =L5+T5+AC5+AK5+AS5+BA5+BI5+BQ5 -> 0
A25: Protección | B25: Kits - CARE Package- (meta hogar) | C25: 2400 | D25: =F6+N6+W6+AE6+AM6+AU6+BC6+BK6 -> 0 | E25: =G6+O6+X6+AF6+AN6+AV6+BD6+BL6 -> 240 | F25: =H6+P6+Y6+AG6+AO6+AW6+BE6+BM6 -> 480 | G25: =I6+Q6+Z6+AH6+AP6+AX6+BF6+BN6 -> 600 | H25: =J6+R6+AA6+AI6+AQ6+AY6+BG6+BO6 -> 600 | I25: =K6+S6+AB6+AJ6+AR6+AZ6+BH6+BP6 -> 480 | J25: =L6+T6+AC6+AK6+AS6+BA6+BI6+BQ6 -> 0
A26: Protección | B26: Kits - CARE Package- (meta personas) | C26: =C7 -> 9600 | D26: =F7+N7+W7+AE7+AM7+AU7+BC7+BK7 -> 0 | E26: =G7+O7+X7+AF7+AN7+AV7+BD7+BL7 -> 960 | F26: =H7+P7+Y7+AG7+AO7+AW7+BE7+BM7 -> 1920 | G26: =I7+Q7+Z7+AH7+AP7+AX7+BF7+BN7 -> 2400 | H26: =J7+R7+AA7+AI7+AQ7+AY7+BG7+BO7 -> 2400 | I26: =K7+S7+AB7+AJ7+AR7+AZ7+BH7+BP7 -> 1920 | J26: =L7+T7+AC7+AK7+AS7+BA7+BI7+BQ7 -> 0
A27: Protección | B27: Espacios seguros mejorados | C27: 8 | D27: =F8+N8+W8+AE8+AM8+AU8+BC8+BK8 -> 0 | E27: =G8+O8+X8+AF8+AN8+AV8+BD8+BL8 -> 0 | F27: =H8+P8+Y8+AG8+AO8+AW8+BE8+BM8 -> 0 | G27: =I8+Q8+Z8+AH8+AP8+AX8+BF8+BN8 -> 8 | H27: =J8+R8+AA8+AI8+AQ8+AY8+BG8+BO8 -> 0 | I27: =K8+S8+AB8+AJ8+AR8+AZ8+BH8+BP8 -> 0 | J27: =L8+T8+AC8+AK8+AS8+BA8+BI8+BQ8 -> 0
A28: Protección | B28: Espacios seguros participantes | C28: =C9 -> 5400 | D28: =F9+N9+W9+AE9+AM9+AU9+BC9+BK9 -> 0 | E28: =G9+O9+X9+AF9+AN9+AV9+BD9+BL9 -> 0 | F28: =H9+P9+Y9+AG9+AO9+AW9+BE9+BM9 -> 0 | G28: =I9+Q9+Z9+AH9+AP9+AX9+BF9+BN9 -> 1080 | H28: =J9+R9+AA9+AI9+AQ9+AY9+BG9+BO9 -> 2160 | I28: =K9+S9+AB9+AJ9+AR9+AZ9+BH9+BP9 -> 2160 | J28: =L9+T9+AC9+AK9+AS9+BA9+BI9+BQ9 -> 0
A29: Salud | B29: Sensibilizaciones salud | C29: 1400 | D29: =F10+N10 -> 0 | E29: =G10+O10 -> 184 | F29: =H10+P10 -> 322 | G29: =I10+Q10 -> 322 | H29: =J10+R10 -> 322 | I29: =K10+S10 -> 250 | J29: =L10+T10 -> 0
A30: Salud | B30: Servicios salud primaria | C30: 2690 | D30: =F11+N11 -> 0 | E30: =G11+O11 -> 288 | F30: =H11+P11 -> 600 | G30: =I11+Q11 -> 600 | H30: =J11+R11 -> 600 | I30: =K11+S11 -> 602 | J30: =L11+T11 -> 0
A31: Salud | B31: Salud primaria personas únicas | C31: 1345 | D31: =F12+N12 -> 0 | E31: =G12+O12 -> 144 | F31: =H12+P12 -> 300 | G31: =I12+Q12 -> 300 | H31: =J12+R12 -> 300 | I31: =K12+S12 -> 301 | J31: =L12+T12 -> 0
A32: Salud | B32: Kits post - parto | C32: 140 | D32: =F13+N13 -> 0 | E32: =G13+O13 -> 14 | F32: =H13+P13 -> 32 | G32: =I13+Q13 -> 32 | H32: =J13+R13 -> 32 | I32: =K13+S13 -> 30 | J32: =L13+T13 -> 0
A33: Salud | B33: Atención VBG | C33: 576 | D33: =F14+N14 -> 0 | E33: =G14+O14 -> 96 | F33: =H14+P14 -> 120 | G33: =I14+Q14 -> 120 | H33: =J14+R14 -> 120 | I33: =K14+S14 -> 120 | J33: =L14+T14 -> 0
A34: MPC | B34: Entrega cash multipropósito (meta hogar) | C34: 576 | D34: =F15+N15 -> 0 | E34: =G15+O15 -> 60 | F34: =H15+P15 -> 128 | G34: =I15+Q15 -> 132 | H34: =J15+R15 -> 128 | I34: =K15+S15 -> 128 | J34: =L15+T15 -> 0
A35: MPC | B35: Entrega cash multipropósito (cantidad de entregas x 3) | C35: 1728 | D35: =F16+N16 -> 0 | E35: =G16+O16 -> 180 | F35: =H16+P16 -> 384 | G35: =I16+Q16 -> 396 | H35: =J16+R16 -> 384 | I35: =K16+S16 -> 384 | J35: =L16+T16 -> 0

Sheet Seguimiento Cauca
A1: SEGUIMIENTO MENSUAL - DEPARTAMENTO DE CAUCA
A3: MUNICIPIO: BUENOS AIRES
A4: Sector | B4: Actividad | C4: TOTAL | F4: May | I4: Jun | L4: Jul | O4: Ago | R4: Sep | U4: Oct | X4: Nov
C5: Meta | D5: Avance | E5: % Av | F5: Meta | G5: Avance | H5: % Av | I5: Meta | J5: Avance | K5: % Av | L5: Meta | M5: Avance | N5: % Av | O5: Meta | P5: Avance | Q5: % Av | R5: Meta | S5: Avance | T5: % Av | U5: Meta | V5: Avance | W5: % Av | X5: Meta | Y5: Avance | Z5: % Av
A6: Protección | B6: Sensibilizaciones general (10%) | C6: ='Detalle metas'!E2 -> 240 | D6: =SUM(G6,J6,M6,P6,S6,V6,Y6) -> 0 | E6: =IFERROR(D6/C6,0) -> 0 | F6: ='Detalle metas'!F2 -> 0 | H6: =IFERROR(G6/F6,0) -> 0 | I6: ='Detalle metas'!G2 -> 24 | K6: =IFERROR(J6/I6,0) -> 0 | L6: ='Detalle metas'!H2 -> 54 | N6: =IFERROR(M6/L6,0) -> 0 | O6: ='Detalle metas'!I2 -> 54 | Q6: =IFERROR(P6/O6,0) -> 0 | R6: ='Detalle metas'!J2 -> 54 | T6: =IFERROR(S6/R6,0) -> 0 | U6: ='Detalle metas'!K2 -> 54 | W6: =IFERROR(V6/U6,0) -> 0 | X6: ='Detalle metas'!L2 -> 0 | Z6: =IFERROR(Y6/X6,0) -> 0
A7: Protección | B7: Sensibilizaciones VBG (80%) | C7: ='Detalle metas'!E3 -> 960 | D7: =SUM(G7,J7,M7,P7,S7,V7,Y7) -> 0 | E7: =IFERROR(D7/C7,0) -> 0 | F7: ='Detalle metas'!F3 -> 0 | H7: =IFERROR(G7/F7,0) -> 0 | I7: ='Detalle metas'!G3 -> 96 | K7: =IFERROR(J7/I7,0) -> 0 | L7: ='Detalle metas'!H3 -> 216 | N7: =IFERROR(M7/L7,0) -> 0 | O7: ='Detalle metas'!I3 -> 216 | Q7: =IFERROR(P7/O7,0) -> 0 | R7: ='Detalle metas'!J3 -> 216 | T7: =IFERROR(S7/R7,0) -> 0 | U7: ='Detalle metas'!K3 -> 216 | W7: =IFERROR(V7/U7,0) -> 0 | X7: ='Detalle metas'!L3 -> 0 | Z7: =IFERROR(Y7/X7,0) -> 0
A8: Protección | B8: Gestión de Casos | C8: ='Detalle metas'!E4 -> 288 | D8: =SUM(G8,J8,M8,P8,S8,V8,Y8) -> 0 | E8: =IFERROR(D8/C8,0) -> 0 | F8: ='Detalle metas'!F4 -> 0 | H8: =IFERROR(G8/F8,0) -> 0 | I8: ='Detalle metas'!G4 -> 48 | K8: =IFERROR(J8/I8,0) -> 0 | L8: ='Detalle metas'!H4 -> 60 | N8: =IFERROR(M8/L8,0) -> 0 | O8: ='Detalle metas'!I4 -> 60 | Q8: =IFERROR(P8/O8,0) -> 0 | R8: ='Detalle metas'!J4 -> 60 | T8: =IFERROR(S8/R8,0) -> 0 | U8: ='Detalle metas'!K4 -> 60 | W8: =IFERROR(V8/U8,0) -> 0 | X8: ='Detalle metas'!L4 -> 0 | Z8: =IFERROR(Y8/X8,0) -> 0
A9: Protección | B9: Cash VBG | C9: ='Detalle metas'!E5 -> 115 | D9: =SUM(G9,J9,M9,P9,S9,V9,Y9) -> 0 | E9: =IFERROR(D9/C9,0) -> 0 | F9: ='Detalle metas'!F5 -> 0 | H9: =IFERROR(G9/F9,0) -> 0 | I9: ='Detalle metas'!G5 -> 15 | K9: =IFERROR(J9/I9,0) -> 0 | L9: ='Detalle metas'!H5 -> 25 | N9: =IFERROR(M9/L9,0) -> 0 | O9: ='Detalle metas'!I5 -> 25 | Q9: =IFERROR(P9/O9,0) -> 0 | R9: ='Detalle metas'!J5 -> 25 | T9: =IFERROR(S9/R9,0) -> 0 | U9: ='Detalle metas'!K5 -> 25 | W9: =IFERROR(V9/U9,0) -> 0 | X9: ='Detalle metas'!L5 -> 0 | Z9: =IFERROR(Y9/X9,0) -> 0
A10: Protección | B10: Kits - CARE Package- (meta hogar) | C10: ='Detalle metas'!E6 -> 300 | D10: =SUM(G10,J10,M10,P10,S10,V10,Y10) -> 0 | E10: =IFERROR(D10/C10,0) -> 0 | F10: ='Detalle metas'!F6 -> 0 | H10: =IFERROR(G10/F10,0) -> 0 | I10: ='Detalle metas'!G6 -> 30 | K10: =IFERROR(J10/I10,0) -> 0 | L10: ='Detalle metas'!H6 -> 60 | N10: =IFERROR(M10/L10,0) -> 0 | O10: ='Detalle metas'!I6 -> 75 | Q10: =IFERROR(P10/O10,0) -> 0 | R10: ='Detalle metas'!J6 -> 75 | T10: =IFERROR(S10/R10,0) -> 0 | U10: ='Detalle metas'!K6 -> 60 | W10: =IFERROR(V10/U10,0) -> 0 | X10: ='Detalle metas'!L6 -> 0 | Z10: =IFERROR(Y10/X10,0) -> 0
A11: Protección | B11: Kits - CARE Package- (meta personas) | C11: ='Detalle metas'!E7 -> 1200 | D11: =SUM(G11,J11,M11,P11,S11,V11,Y11) -> 0 | E11: =IFERROR(D11/C11,0) -> 0 | F11: ='Detalle metas'!F7 -> 0 | H11: =IFERROR(G11/F11,0) -> 0 | I11: ='Detalle metas'!G7 -> 120 | J11: =J10*4 -> 0 | K11: =IFERROR(J11/I11,0) -> 0 | L11: ='Detalle metas'!H7 -> 240 | M11: =M10*4 -> 0 | N11: =IFERROR(M11/L11,0) -> 0 | O11: ='Detalle metas'!I7 -> 300 | P11: =P10*4 -> 0 | Q11: =IFERROR(P11/O11,0) -> 0 | R11: ='Detalle metas'!J7 -> 300 | S11: =S10*4 -> 0 | T11: =IFERROR(S11/R11,0) -> 0 | U11: ='Detalle metas'!K7 -> 240 | V11: =V10*4 -> 0 | W11: =IFERROR(V11/U11,0) -> 0 | Z11: =IFERROR(Y11/X11,0) -> 0
A12: Protección | B12: Espacios seguros mejorados | C12: ='Detalle metas'!E8 -> 1 | D12: =SUM(G12,J12,M12,P12,S12,V12,Y12) -> 0 | E12: =IFERROR(D12/C12,0) -> 0 | F12: ='Detalle metas'!F8 -> 0 | H12: =IFERROR(G12/F12,0) -> 0 | I12: ='Detalle metas'!G8 -> 0 | K12: =IFERROR(J12/I12,0) -> 0 | L12: ='Detalle metas'!H8 -> 0 | N12: =IFERROR(M12/L12,0) -> 0 | O12: ='Detalle metas'!I8 -> 1 | Q12: =IFERROR(P12/O12,0) -> 0 | R12: ='Detalle metas'!J8 -> 0 | T12: =IFERROR(S12/R12,0) -> 0 | U12: ='Detalle metas'!K8 -> 0 | W12: =IFERROR(V12/U12,0) -> 0 | X12: ='Detalle metas'!L8 -> 0 | Z12: =IFERROR(Y12/X12,0) -> 0
A13: Protección | B13: Espacios seguros participantes | C13: ='Detalle metas'!E9 -> 900 | D13: =SUM(G13,J13,M13,P13,S13,V13,Y13) -> 0 | E13: =IFERROR(D13/C13,0) -> 0 | F13: ='Detalle metas'!F9 -> 0 | H13: =IFERROR(G13/F13,0) -> 0 | I13: ='Detalle metas'!G9 -> 0 | K13: =IFERROR(J13/I13,0) -> 0 | L13: ='Detalle metas'!H9 -> 0 | N13: =IFERROR(M13/L13,0) -> 0 | O13: ='Detalle metas'!I9 -> 180 | Q13: =IFERROR(P13/O13,0) -> 0 | R13: ='Detalle metas'!J9 -> 360 | T13: =IFERROR(S13/R13,0) -> 0 | U13: ='Detalle metas'!K9 -> 360 | W13: =IFERROR(V13/U13,0) -> 0 | X13: ='Detalle metas'!L9 -> 0 | Z13: =IFERROR(Y13/X13,0) -> 0
A14: Salud | B14: Sensibilizaciones | C14: ='Detalle metas'!E10 -> 700 | D14: =SUM(G14,J14,M14,P14,S14,V14,Y14) -> 0 | E14: =IFERROR(D14/C14,0) -> 0 | F14: ='Detalle metas'!F10 -> 0 | H14: =IFERROR(G14/F14,0) -> 0 | I14: ='Detalle metas'!G10 -> 92 | K14: =IFERROR(J14/I14,0) -> 0 | L14: ='Detalle metas'!H10 -> 161 | N14: =IFERROR(M14/L14,0) -> 0 | O14: ='Detalle metas'!I10 -> 161 | Q14: =IFERROR(P14/O14,0) -> 0 | R14: ='Detalle metas'!J10 -> 161 | T14: =IFERROR(S14/R14,0) -> 0 | U14: ='Detalle metas'!K10 -> 125 | W14: =IFERROR(V14/U14,0) -> 0 | X14: ='Detalle metas'!L10 -> 0 | Z14: =IFERROR(Y14/X14,0) -> 0
A15: Salud | B15: Servicios salud primaria | C15: ='Detalle metas'!E11 -> 1345 | D15: =SUM(G15,J15,M15,P15,S15,V15,Y15) -> 0 | E15: =IFERROR(D15/C15,0) -> 0 | F15: ='Detalle metas'!F11 -> 0 | H15: =IFERROR(G15/F15,0) -> 0 | I15: ='Detalle metas'!G11 -> 144 | K15: =IFERROR(J15/I15,0) -> 0 | L15: ='Detalle metas'!H11 -> 300 | N15: =IFERROR(M15/L15,0) -> 0 | O15: ='Detalle metas'!I11 -> 300 | Q15: =IFERROR(P15/O15,0) -> 0 | R15: ='Detalle metas'!J11 -> 300 | T15: =IFERROR(S15/R15,0) -> 0 | U15: ='Detalle metas'!K11 -> 301 | W15: =IFERROR(V15/U15,0) -> 0 | X15: ='Detalle metas'!L11 -> 0 | Z15: =IFERROR(Y15/X15,0) -> 0
A16: Salud | B16: Salud primaria personas únicas | C16: ='Detalle metas'!E12 -> 673 | D16: =SUM(G16,J16,M16,P16,S16,V16,Y16) -> 0 | E16: =IFERROR(D16/C16,0) -> 0 | F16: ='Detalle metas'!F12 -> 0 | H16: =IFERROR(G16/F16,0) -> 0 | I16: ='Detalle metas'!G12 -> 72 | K16: =IFERROR(J16/I16,0) -> 0 | L16: ='Detalle metas'!H12 -> 150 | N16: =IFERROR(M16/L16,0) -> 0 | O16: ='Detalle metas'!I12 -> 150 | Q16: =IFERROR(P16/O16,0) -> 0 | R16: ='Detalle metas'!J12 -> 150 | T16: =IFERROR(S16/R16,0) -> 0 | U16: ='Detalle metas'!K12 -> 151 | W16: =IFERROR(V16/U16,0) -> 0 | X16: ='Detalle metas'!L12 -> 0 | Z16: =IFERROR(Y16/X16,0) -> 0
A17: Salud | B17: Kits post - parto | C17: ='Detalle metas'!E13 -> 70 | D17: =SUM(G17,J17,M17,P17,S17,V17,Y17) -> 0 | E17: =IFERROR(D17/C17,0) -> 0 | F17: ='Detalle metas'!F13 -> 0 | H17: =IFERROR(G17/F17,0) -> 0 | I17: ='Detalle metas'!G13 -> 7 | K17: =IFERROR(J17/I17,0) -> 0 | L17: ='Detalle metas'!H13 -> 16 | N17: =IFERROR(M17/L17,0) -> 0 | O17: ='Detalle metas'!I13 -> 16 | Q17: =IFERROR(P17/O17,0) -> 0 | R17: ='Detalle metas'!J13 -> 16 | T17: =IFERROR(S17/R17,0) -> 0 | U17: ='Detalle metas'!K13 -> 15 | W17: =IFERROR(V17/U17,0) -> 0 | X17: ='Detalle metas'!L13 -> 0 | Z17: =IFERROR(Y17/X17,0) -> 0
A18: Salud | B18: Atención VBG | C18: ='Detalle metas'!E14 -> 288 | D18: =SUM(G18,J18,M18,P18,S18,V18,Y18) -> 0 | E18: =IFERROR(D18/C18,0) -> 0 | F18: ='Detalle metas'!F14 -> 0 | H18: =IFERROR(G18/F18,0) -> 0 | I18: ='Detalle metas'!G14 -> 48 | K18: =IFERROR(J18/I18,0) -> 0 | L18: ='Detalle metas'!H14 -> 60 | N18: =IFERROR(M18/L18,0) -> 0 | O18: ='Detalle metas'!I14 -> 60 | Q18: =IFERROR(P18/O18,0) -> 0 | R18: ='Detalle metas'!J14 -> 60 | T18: =IFERROR(S18/R18,0) -> 0 | U18: ='Detalle metas'!K14 -> 60 | W18: =IFERROR(V18/U18,0) -> 0 | X18: ='Detalle metas'!L14 -> 0 | Z18: =IFERROR(Y18/X18,0) -> 0
A19: MPC | B19: Entrega cash multipropósito (meta hogar) | C19: ='Detalle metas'!E15 -> 288 | D19: =SUM(G19,J19,M19,P19,S19,V19,Y19) -> 0 | E19: =IFERROR(D19/C19,0) -> 0 | F19: ='Detalle metas'!F15 -> 0 | H19: =IFERROR(G19/F19,0) -> 0 | I19: ='Detalle metas'!G15 -> 30 | K19: =IFERROR(J19/I19,0) -> 0 | L19: ='Detalle metas'!H15 -> 64 | N19: =IFERROR(M19/L19,0) -> 0 | O19: ='Detalle metas'!I15 -> 66 | Q19: =IFERROR(P19/O19,0) -> 0 | R19: ='Detalle metas'!J15 -> 64 | T19: =IFERROR(S19/R19,0) -> 0 | U19: ='Detalle metas'!K15 -> 64 | W19: =IFERROR(V19/U19,0) -> 0 | X19: ='Detalle metas'!L15 -> 0 | Z19: =IFERROR(Y19/X19,0) -> 0
A20: MPC | B20: Entrega cash multipropósito (cantidad de entregas x 3) | C20: ='Detalle metas'!E16 -> 864 | D20: =SUM(G20,J20,M20,P20,S20,V20,Y20) -> 0 | E20: =IFERROR(D20/C20,0) -> 0 | F20: ='Detalle metas'!F16 -> 0 | H20: =IFERROR(G20/F20,0) -> 0 | I20: ='Detalle metas'!G16 -> 90 | K20: =IFERROR(J20/I20,0) -> 0 | L20: ='Detalle metas'!H16 -> 192 | N20: =IFERROR(M20/L20,0) -> 0 | O20: ='Detalle metas'!I16 -> 198 | Q20: =IFERROR(P20/O20,0) -> 0 | R20: ='Detalle metas'!J16 -> 192 | T20: =IFERROR(S20/R20,0) -> 0 | U20: ='Detalle metas'!K16 -> 192 | W20: =IFERROR(V20/U20,0) -> 0 | X20: ='Detalle metas'!L16 -> 0 | Z20: =IFERROR(Y20/X20,0) -> 0
A22: MUNICIPIO: MORALES
A23: Sector | B23: Actividad | C23: TOTAL | F23: May | I23: Jun | L23: Jul | O23: Ago | R23: Sep | U23: Oct | X23: Nov
C24: Meta | D24: Avance | E24: % Av | F24: Meta | G24: Avance | H24: % Av | I24: Meta | J24: Avance | K24: % Av | L24: Meta | M24: Avance | N24: % Av | O24: Meta | P24: Avance | Q24: % Av | R24: Meta | S24: Avance | T24: % Av | U24: Meta | V24: Avance | W24: % Av | X24: Meta | Y24: Avance | Z24: % Av
A25: Protección | B25: Sensibilizaciones general (10%) | C25: ='Detalle metas'!M2 -> 240 | D25: =SUM(G25,J25,M25,P25,S25,V25,Y25) -> 0 | E25: =IFERROR(D25/C25,0) -> 0 | F25: ='Detalle metas'!N2 -> 0 | H25: =IFERROR(G25/F25,0) -> 0 | I25: ='Detalle metas'!O2 -> 24 | K25: =IFERROR(J25/I25,0) -> 0 | L25: ='Detalle metas'!P2 -> 54 | N25: =IFERROR(M25/L25,0) -> 0 | O25: ='Detalle metas'!Q2 -> 54 | Q25: =IFERROR(P25/O25,0) -> 0 | R25: ='Detalle metas'!R2 -> 54 | T25: =IFERROR(S25/R25,0) -> 0 | U25: ='Detalle metas'!S2 -> 54 | W25: =IFERROR(V25/U25,0) -> 0 | X25: ='Detalle metas'!T2 -> 0 | Z25: =IFERROR(Y25/X25,0) -> 0
A26: Protección | B26: Sensibilizaciones VBG (80%) | C26: ='Detalle metas'!M3 -> 960 | D26: =SUM(G26,J26,M26,P26,S26,V26,Y26) -> 0 | E26: =IFERROR(D26/C26,0) -> 0 | F26: ='Detalle metas'!N3 -> 0 | H26: =IFERROR(G26/F26,0) -> 0 | I26: ='Detalle metas'!O3 -> 96 | K26: =IFERROR(J26/I26,0) -> 0 | L26: ='Detalle metas'!P3 -> 216 | N26: =IFERROR(M26/L26,0) -> 0 | O26: ='Detalle metas'!Q3 -> 216 | Q26: =IFERROR(P26/O26,0) -> 0 | R26: ='Detalle metas'!R3 -> 216 | T26: =IFERROR(S26/R26,0) -> 0 | U26: ='Detalle metas'!S3 -> 216 | W26: =IFERROR(V26/U26,0) -> 0 | X26: ='Detalle metas'!T3 -> 0 | Z26: =IFERROR(Y26/X26,0) -> 0
A27: Protección | B27: Gestión de Casos | C27: ='Detalle metas'!M4 -> 288 | D27: =SUM(G27,J27,M27,P27,S27,V27,Y27) -> 0 | E27: =IFERROR(D27/C27,0) -> 0 | F27: ='Detalle metas'!N4 -> 0 | H27: =IFERROR(G27/F27,0) -> 0 | I27: ='Detalle metas'!O4 -> 48 | K27: =IFERROR(J27/I27,0) -> 0 | L27: ='Detalle metas'!P4 -> 60 | N27: =IFERROR(M27/L27,0) -> 0 | O27: ='Detalle metas'!Q4 -> 60 | Q27: =IFERROR(P27/O27,0) -> 0 | R27: ='Detalle metas'!R4 -> 60 | T27: =IFERROR(S27/R27,0) -> 0 | U27: ='Detalle metas'!S4 -> 60 | W27: =IFERROR(V27/U27,0) -> 0 | X27: ='Detalle metas'!T4 -> 0 | Z27: =IFERROR(Y27/X27,0) -> 0
A28: Protección | B28: Cash VBG | C28: ='Detalle metas'!M5 -> 115 | D28: =SUM(G28,J28,M28,P28,S28,V28,Y28) -> 0 | E28: =IFERROR(D28/C28,0) -> 0 | F28: ='Detalle metas'!N5 -> 0 | H28: =IFERROR(G28/F28,0) -> 0 | I28: ='Detalle metas'!O5 -> 15 | K28: =IFERROR(J28/I28,0) -> 0 | L28: ='Detalle metas'!P5 -> 25 | N28: =IFERROR(M28/L28,0) -> 0 | O28: ='Detalle metas'!Q5 -> 25 | Q28: =IFERROR(P28/O28,0) -> 0 | R28: ='Detalle metas'!R5 -> 25 | T28: =IFERROR(S28/R28,0) -> 0 | U28: ='Detalle metas'!S5 -> 25 | W28: =IFERROR(V28/U28,0) -> 0 | X28: ='Detalle metas'!T5 -> 0 | Z28: =IFERROR(Y28/X28,0) -> 0
A29: Protección | B29: Kits - CARE Package- (meta hogar) | C29: ='Detalle metas'!M6 -> 300 | D29: =SUM(G29,J29,M29,P29,S29,V29,Y29) -> 0 | E29: =IFERROR(D29/C29,0) -> 0 | F29: ='Detalle metas'!N6 -> 0 | H29: =IFERROR(G29/F29,0) -> 0 | I29: ='Detalle metas'!O6 -> 30 | K29: =IFERROR(J29/I29,0) -> 0 | L29: ='Detalle metas'!P6 -> 60 | N29: =IFERROR(M29/L29,0) -> 0 | O29: ='Detalle metas'!Q6 -> 75 | Q29: =IFERROR(P29/O29,0) -> 0 | R29: ='Detalle metas'!R6 -> 75 | T29: =IFERROR(S29/R29,0) -> 0 | U29: ='Detalle metas'!S6 -> 60 | W29: =IFERROR(V29/U29,0) -> 0 | X29: ='Detalle metas'!T6 -> 0 | Z29: =IFERROR(Y29/X29,0) -> 0
A30: Protección | B30: Kits - CARE Package- (meta personas) | C30: ='Detalle metas'!M7 -> 1200 | D30: =SUM(G30,J30,M30,P30,S30,V30,Y30) -> 0 | E30: =IFERROR(D30/C30,0) -> 0 | F30: ='Detalle metas'!N7 -> 0 | H30: =IFERROR(G30/F30,0) -> 0 | I30: ='Detalle metas'!O7 -> 120 | J30: =J29*4 -> 0 | K30: =IFERROR(J30/I30,0) -> 0 | L30: ='Detalle metas'!P7 -> 240 | M30: =M29*4 -> 0 | N30: =IFERROR(M30/L30,0) -> 0 | O30: ='Detalle metas'!Q7 -> 300 | P30: =P29*4 -> 0 | Q30: =IFERROR(P30/O30,0) -> 0 | R30: ='Detalle metas'!R7 -> 300 | S30: =S29*4 -> 0 | T30: =IFERROR(S30/R30,0) -> 0 | U30: ='Detalle metas'!S7 -> 240 | V30: =V29*4 -> 0 | W30: =IFERROR(V30/U30,0) -> 0 | X30: ='Detalle metas'!T7 -> 0 | Y30: =Y29*4 -> 0 | Z30: =IFERROR(Y30/X30,0) -> 0
A31: Protección | B31: Espacios seguros mejorados | C31: ='Detalle metas'!M8 -> 1 | D31: =SUM(G31,J31,M31,P31,S31,V31,Y31) -> 0 | E31: =IFERROR(D31/C31,0) -> 0 | F31: ='Detalle metas'!N8 -> 0 | H31: =IFERROR(G31/F31,0) -> 0 | I31: ='Detalle metas'!O8 -> 0 | K31: =IFERROR(J31/I31,0) -> 0 | L31: ='Detalle metas'!P8 -> 0 | N31: =IFERROR(M31/L31,0) -> 0 | O31: ='Detalle metas'!Q8 -> 1 | Q31: =IFERROR(P31/O31,0) -> 0 | R31: ='Detalle metas'!R8 -> 0 | T31: =IFERROR(S31/R31,0) -> 0 | U31: ='Detalle metas'!S8 -> 0 | W31: =IFERROR(V31/U31,0) -> 0 | X31: ='Detalle metas'!T8 -> 0 | Z31: =IFERROR(Y31/X31,0) -> 0
A32: Protección | B32: Espacios seguros participantes | C32: ='Detalle metas'!M9 -> 900 | D32: =SUM(G32,J32,M32,P32,S32,V32,Y32) -> 0 | E32: =IFERROR(D32/C32,0) -> 0 | F32: ='Detalle metas'!N9 -> 0 | H32: =IFERROR(G32/F32,0) -> 0 | I32: ='Detalle metas'!O9 -> 0 | K32: =IFERROR(J32/I32,0) -> 0 | L32: ='Detalle metas'!P9 -> 0 | N32: =IFERROR(M32/L32,0) -> 0 | O32: ='Detalle metas'!Q9 -> 180 | Q32: =IFERROR(P32/O32,0) -> 0 | R32: ='Detalle metas'!R9 -> 360 | T32: =IFERROR(S32/R32,0) -> 0 | U32: ='Detalle metas'!S9 -> 360 | W32: =IFERROR(V32/U32,0) -> 0 | X32: ='Detalle metas'!T9 -> 0 | Z32: =IFERROR(Y32/X32,0) -> 0
A33: Salud | B33: Sensibilizaciones | C33: ='Detalle metas'!M10 -> 700 | D33: =SUM(G33,J33,M33,P33,S33,V33,Y33) -> 0 | E33: =IFERROR(D33/C33,0) -> 0 | F33: ='Detalle metas'!N10 -> 0 | H33: =IFERROR(G33/F33,0) -> 0 | I33: ='Detalle metas'!O10 -> 92 | K33: =IFERROR(J33/I33,0) -> 0 | L33: ='Detalle metas'!P10 -> 161 | N33: =IFERROR(M33/L33,0) -> 0 | O33: ='Detalle metas'!Q10 -> 161 | Q33: =IFERROR(P33/O33,0) -> 0 | R33: ='Detalle metas'!R10 -> 161 | T33: =IFERROR(S33/R33,0) -> 0 | U33: ='Detalle metas'!S10 -> 125 | W33: =IFERROR(V33/U33,0) -> 0 | X33: ='Detalle metas'!T10 -> 0 | Z33: =IFERROR(Y33/X33,0) -> 0
A34: Salud | B34: Servicios salud primaria | C34: ='Detalle metas'!M11 -> 1345 | D34: =SUM(G34,J34,M34,P34,S34,V34,Y34) -> 0 | E34: =IFERROR(D34/C34,0) -> 0 | F34: ='Detalle metas'!N11 -> 0 | H34: =IFERROR(G34/F34,0) -> 0 | I34: ='Detalle metas'!O11 -> 144 | K34: =IFERROR(J34/I34,0) -> 0 | L34: ='Detalle metas'!P11 -> 300 | N34: =IFERROR(M34/L34,0) -> 0 | O34: ='Detalle metas'!Q11 -> 300 | Q34: =IFERROR(P34/O34,0) -> 0 | R34: ='Detalle metas'!R11 -> 300 | T34: =IFERROR(S34/R34,0) -> 0 | U34: ='Detalle metas'!S11 -> 301 | W34: =IFERROR(V34/U34,0) -> 0 | X34: ='Detalle metas'!T11 -> 0 | Z34: =IFERROR(Y34/X34,0) -> 0
A35: Salud | B35: Salud primaria personas únicas | C35: ='Detalle metas'!M12 -> 672 | D35: =SUM(G35,J35,M35,P35,S35,V35,Y35) -> 0 | E35: =IFERROR(D35/C35,0) -> 0 | F35: ='Detalle metas'!N12 -> 0 | H35: =IFERROR(G35/F35,0) -> 0 | I35: ='Detalle metas'!O12 -> 72 | K35: =IFERROR(J35/I35,0) -> 0 | L35: ='Detalle metas'!P12 -> 150 | N35: =IFERROR(M35/L35,0) -> 0 | O35: ='Detalle metas'!Q12 -> 150 | Q35: =IFERROR(P35/O35,0) -> 0 | R35: ='Detalle metas'!R12 -> 150 | T35: =IFERROR(S35/R35,0) -> 0 | U35: ='Detalle metas'!S12 -> 150 | W35: =IFERROR(V35/U35,0) -> 0 | X35: ='Detalle metas'!T12 -> 0 | Z35: =IFERROR(Y35/X35,0) -> 0
A36: Salud | B36: Kits post - parto | C36: ='Detalle metas'!M13 -> 70 | D36: =SUM(G36,J36,M36,P36,S36,V36,Y36) -> 0 | E36: =IFERROR(D36/C36,0) -> 0 | F36: ='Detalle metas'!N13 -> 0 | H36: =IFERROR(G36/F36,0) -> 0 | I36: ='Detalle metas'!O13 -> 7 | K36: =IFERROR(J36/I36,0) -> 0 | L36: ='Detalle metas'!P13 -> 16 | N36: =IFERROR(M36/L36,0) -> 0 | O36: ='Detalle metas'!Q13 -> 16 | Q36: =IFERROR(P36/O36,0) -> 0 | R36: ='Detalle metas'!R13 -> 16 | T36: =IFERROR(S36/R36,0) -> 0 | U36: ='Detalle metas'!S13 -> 15 | W36: =IFERROR(V36/U36,0) -> 0 | X36: ='Detalle metas'!T13 -> 0 | Z36: =IFERROR(Y36/X36,0) -> 0
A37: Salud | B37: Atención VBG | C37: ='Detalle metas'!M14 -> 288 | D37: =SUM(G37,J37,M37,P37,S37,V37,Y37) -> 0 | E37: =IFERROR(D37/C37,0) -> 0 | F37: ='Detalle metas'!N14 -> 0 | H37: =IFERROR(G37/F37,0) -> 0 | I37: ='Detalle metas'!O14 -> 48 | K37: =IFERROR(J37/I37,0) -> 0 | L37: ='Detalle metas'!P14 -> 60 | N37: =IFERROR(M37/L37,0) -> 0 | O37: ='Detalle metas'!Q14 -> 60 | Q37: =IFERROR(P37/O37,0) -> 0 | R37: ='Detalle metas'!R14 -> 60 | T37: =IFERROR(S37/R37,0) -> 0 | U37: ='Detalle metas'!S14 -> 60 | W37: =IFERROR(V37/U37,0) -> 0 | X37: ='Detalle metas'!T14 -> 0 | Z37: =IFERROR(Y37/X37,0) -> 0
A38: MPC | B38: Entrega cash multipropósito (meta hogar) | C38: ='Detalle metas'!M15 -> 288 | D38: =SUM(G38,J38,M38,P38,S38,V38,Y38) -> 0 | E38: =IFERROR(D38/C38,0) -> 0 | F38: ='Detalle metas'!N15 -> 0 | H38: =IFERROR(G38/F38,0) -> 0 | I38: ='Detalle metas'!O15 -> 30 | K38: =IFERROR(J38/I38,0) -> 0 | L38: ='Detalle metas'!P15 -> 64 | N38: =IFERROR(M38/L38,0) -> 0 | O38: ='Detalle metas'!Q15 -> 66 | Q38: =IFERROR(P38/O38,0) -> 0 | R38: ='Detalle metas'!R15 -> 64 | T38: =IFERROR(S38/R38,0) -> 0 | U38: ='Detalle metas'!S15 -> 64 | W38: =IFERROR(V38/U38,0) -> 0 | X38: ='Detalle metas'!T15 -> 0 | Z38: =IFERROR(Y38/X38,0) -> 0
A39: MPC | B39: Entrega cash multipropósito (cantidad de entregas x 3) | C39: ='Detalle metas'!M16 -> 864 | D39: =SUM(G39,J39,M39,P39,S39,V39,Y39) -> 0 | E39: =IFERROR(D39/C39,0) -> 0 | F39: ='Detalle metas'!N16 -> 0 | H39: =IFERROR(G39/F39,0) -> 0 | I39: ='Detalle metas'!O16 -> 90 | K39: =IFERROR(J39/I39,0) -> 0 | L39: ='Detalle metas'!P16 -> 192 | N39: =IFERROR(M39/L39,0) -> 0 | O39: ='Detalle metas'!Q16 -> 198 | Q39: =IFERROR(P39/O39,0) -> 0 | R39: ='Detalle metas'!R16 -> 192 | T39: =IFERROR(S39/R39,0) -> 0 | U39: ='Detalle metas'!S16 -> 192 | W39: =IFERROR(V39/U39,0) -> 0 | X39: ='Detalle metas'!T16 -> 0 | Z39: =IFERROR(Y39/X39,0) -> 0
A41: CONSOLIDADO CAUCA
A42: Sector | B42: Actividad | C42: TOTAL | F42: May | I42: Jun | L42: Jul | O42: Ago | R42: Sep | U42: Oct | X42: Nov
C43: Meta | D43: Avance | E43: % Av | F43: Meta | G43: Avance | H43: % Av | I43: Meta | J43: Avance | K43: % Av | L43: Meta | M43: Avance | N43: % Av | O43: Meta | P43: Avance | Q43: % Av | R43: Meta | S43: Avance | T43: % Av | U43: Meta | V43: Avance | W43: % Av | X43: Meta | Y43: Avance | Z43: % Av
...

Sheet Seguimiento NdS
A1: SEGUIMIENTO MENSUAL - DEPARTAMENTO DE NORTE DE SANTANDER
A3: MUNICIPIO: ABREGO
A4: Sector | B4: Actividad | C4: TOTAL | F4: May | I4: Jun | L4: Jul | O4: Ago | R4: Sep | U4: Oct | X4: Nov
C5: Meta | D5: Avance | E5: % Av | F5: Meta | G5: Avance | H5: % Av | I5: Meta | J5: Avance | K5: % Av | L5: Meta | M5: Avance | N5: % Av | O5: Meta | P5: Avance | Q5: % Av | R5: Meta | S5: Avance | T5: % Av | U5: Meta | V5: Avance | W5: % Av | X5: Meta | Y5: Avance | Z5: % Av
A6: Protección | B6: Sensibilizaciones general (10%) | C6: ='Detalle metas'!V2 -> 240 | D6: =SUM(G6,J6,M6,P6,S6,V6,Y6) -> 0 | E6: =IFERROR(D6/C6,0) -> 0 | F6: ='Detalle metas'!W2 -> 0 | H6: =IFERROR(G6/F6,0) -> 0 | I6: ='Detalle metas'!X2 -> 24 | K6: =IFERROR(J6/I6,0) -> 0 | L6: ='Detalle metas'!Y2 -> 54 | N6: =IFERROR(M6/L6,0) -> 0 | O6: ='Detalle metas'!Z2 -> 54 | Q6: =IFERROR(P6/O6,0) -> 0 | R6: ='Detalle metas'!AA2 -> 54 | T6: =IFERROR(S6/R6,0) -> 0 | U6: ='Detalle metas'!AB2 -> 54 | W6: =IFERROR(V6/U6,0) -> 0 | X6: ='Detalle metas'!AC2 -> 0 | Z6: =IFERROR(Y6/X6,0) -> 0
A7: Protección | B7: Sensibilizaciones VBG (80%) | C7: ='Detalle metas'!V3 -> 960 | D7: =SUM(G7,J7,M7,P7,S7,V7,Y7) -> 0 | E7: =IFERROR(D7/C7,0) -> 0 | F7: ='Detalle metas'!W3 -> 0 | H7: =IFERROR(G7/F7,0) -> 0 | I7: ='Detalle metas'!X3 -> 96 | K7: =IFERROR(J7/I7,0) -> 0 | L7: ='Detalle metas'!Y3 -> 216 | N7: =IFERROR(M7/L7,0) -> 0 | O7: ='Detalle metas'!Z3 -> 216 | Q7: =IFERROR(P7/O7,0) -> 0 | R7: ='Detalle metas'!AA3 -> 216 | T7: =IFERROR(S7/R7,0) -> 0 | U7: ='Detalle metas'!AB3 -> 216 | W7: =IFERROR(V7/U7,0) -> 0 | X7: ='Detalle metas'!AC3 -> 0 | Z7: =IFERROR(Y7/X7,0) -> 0
A8: Protección | B8: Gestión de Casos | C8: ='Detalle metas'!V4 -> 96 | D8: =SUM(G8,J8,M8,P8,S8,V8,Y8) -> 0 | E8: =IFERROR(D8/C8,0) -> 0 | F8: ='Detalle metas'!W4 -> 0 | H8: =IFERROR(G8/F8,0) -> 0 | I8: ='Detalle metas'!X4 -> 16 | K8: =IFERROR(J8/I8,0) -> 0 | L8: ='Detalle metas'!Y4 -> 20 | N8: =IFERROR(M8/L8,0) -> 0 | O8: ='Detalle metas'!Z4 -> 20 | Q8: =IFERROR(P8/O8,0) -> 0 | R8: ='Detalle metas'!AA4 -> 20 | T8: =IFERROR(S8/R8,0) -> 0 | U8: ='Detalle metas'!AB4 -> 20 | W8: =IFERROR(V8/U8,0) -> 0 | X8: ='Detalle metas'!AC4 -> 0 | Z8: =IFERROR(Y8/X8,0) -> 0
A9: Protección | B9: Cash VBG | C9: ='Detalle metas'!V5 -> 29 | D9: =SUM(G9,J9,M9,P9,S9,V9,Y9) -> 0 | E9: =IFERROR(D9/C9,0) -> 0 | F9: ='Detalle metas'!W5 -> 0 | H9: =IFERROR(G9/F9,0) -> 0 | I9: ='Detalle metas'!X5 -> 3 | K9: =IFERROR(J9/I9,0) -> 0 | L9: ='Detalle metas'!Y5 -> 7 | N9: =IFERROR(M9/L9,0) -> 0 | O9: ='Detalle metas'!Z5 -> 7 | Q9: =IFERROR(P9/O9,0) -> 0 | R9: ='Detalle metas'!AA5 -> 7 | T9: =IFERROR(S9/R9,0) -> 0 | U9: ='Detalle metas'!AB5 -> 5 | W9: =IFERROR(V9/U9,0) -> 0 | X9: ='Detalle metas'!AC5 -> 0 | Z9: =IFERROR(Y9/X9,0) -> 0
A10: Protección | B10: Kits - CARE Package- (meta hogar) | C10: ='Detalle metas'!V6 -> 300 | D10: =SUM(G10,J10,M10,P10,S10,V10,Y10) -> 0 | E10: =IFERROR(D10/C10,0) -> 0 | F10: ='Detalle metas'!W6 -> 0 | H10: =IFERROR(G10/F10,0) -> 0 | I10: ='Detalle metas'!X6 -> 30 | K10: =IFERROR(J10/I10,0) -> 0 | L10: ='Detalle metas'!Y6 -> 60 | N10: =IFERROR(M10/L10,0) -> 0 | O10: ='Detalle metas'!Z6 -> 75 | Q10: =IFERROR(P10/O10,0) -> 0 | R10: ='Detalle metas'!AA6 -> 75 | T10: =IFERROR(S10/R10,0) -> 0 | U10: ='Detalle metas'!AB6 -> 60 | W10: =IFERROR(V10/U10,0) -> 0 | X10: ='Detalle metas'!AC6 -> 0 | Z10: =IFERROR(Y10/X10,0) -> 0
A11: Protección | B11: Kits - CARE Package- (meta personas) | C11: ='Detalle metas'!V7 -> 1200 | D11: =SUM(G11,J11,M11,P11,S11,V11,Y11) -> 0 | E11: =IFERROR(D11/C11,0) -> 0 | F11: ='Detalle metas'!W7 -> 0 | H11: =IFERROR(G11/F11,0) -> 0 | I11: ='Detalle metas'!X7 -> 120 | J11: =J10*4 -> 0 | K11: =IFERROR(J11/I11,0) -> 0 | L11: ='Detalle metas'!Y7 -> 240 | M11: =M10*4 -> 0 | N11: =IFERROR(M11/L11,0) -> 0 | O11: ='Detalle metas'!Z7 -> 300 | P11: =P10*4 -> 0 | Q11: =IFERROR(P11/O11,0) -> 0 | R11: ='Detalle metas'!AA7 -> 300 | S11: =S10*4 -> 0 | T11: =IFERROR(S11/R11,0) -> 0 | U11: ='Detalle metas'!AB7 -> 240 | V11: =V10*4 -> 0 | W11: =IFERROR(V11/U11,0) -> 0 | X11: ='Detalle metas'!AC7 -> 0 | Y11: =Y10*4 -> 0 | Z11: =IFERROR(Y11/X11,0) -> 0
A12: Protección | B12: Espacios seguros mejorados | C12: ='Detalle metas'!V8 -> 1 | D12: =SUM(G12,J12,M12,P12,S12,V12,Y12) -> 0 | E12: =IFERROR(D12/C12,0) -> 0 | F12: ='Detalle metas'!W8 -> 0 | H12: =IFERROR(G12/F12,0) -> 0 | I12: ='Detalle metas'!X8 -> 0 | K12: =IFERROR(J12/I12,0) -> 0 | L12: ='Detalle metas'!Y8 -> 0 | N12: =IFERROR(M12/L12,0) -> 0 | O12: ='Detalle metas'!Z8 -> 1 | Q12: =IFERROR(P12/O12,0) -> 0 | R12: ='Detalle metas'!AA8 -> 0 | T12: =IFERROR(S12/R12,0) -> 0 | U12: ='Detalle metas'!AB8 -> 0 | W12: =IFERROR(V12/U12,0) -> 0 | X12: ='Detalle metas'!AC8 -> 0 | Z12: =IFERROR(Y12/X12,0) -> 0
A13: Protección | B13: Espacios seguros participantes | C13: ='Detalle metas'!V9 -> 900 | D13: =SUM(G13,J13,M13,P13,S13,V13,Y13) -> 0 | E13: =IFERROR(D13/C13,0) -> 0 | F13: ='Detalle metas'!W9 -> 0 | H13: =IFERROR(G13/F13,0) -> 0 | I13: ='Detalle metas'!X9 -> 0 | K13: =IFERROR(J13/I13,0) -> 0 | L13: ='Detalle metas'!Y9 -> 0 | N13: =IFERROR(M13/L13,0) -> 0 | O13: ='Detalle metas'!Z9 -> 180 | Q13: =IFERROR(P13/O13,0) -> 0 | R13: ='Detalle metas'!AA9 -> 360 | T13: =IFERROR(S13/R13,0) -> 0 | U13: ='Detalle metas'!AB9 -> 360 | W13: =IFERROR(V13/U13,0) -> 0 | X13: ='Detalle metas'!AC9 -> 0 | Z13: =IFERROR(Y13/X13,0) -> 0
A15: MUNICIPIO: OCAÑA
A16: Sector | B16: Actividad | C16: TOTAL | F16: May | I16: Jun | L16: Jul | O16: Ago | R16: Sep | U16: Oct | X16: Nov
C17: Meta | D17: Avance | E17: % Av | F17: Meta | G17: Avance | H17: % Av | I17: Meta | J17: Avance | K17: % Av | L17: Meta | M17: Avance | N17: % Av | O17: Meta | P17: Avance | Q17: % Av | R17: Meta | S17: Avance | T17: % Av | U17: Meta | V17: Avance | W17: % Av | X17: Meta | Y17: Avance | Z17: % Av
A18: Protección | B18: Sensibilizaciones general (10%) | C18: ='Detalle metas'!AD2 -> 240 | D18: =SUM(G18,J18,M18,P18,S18,V18,Y18) -> 0 | E18: =IFERROR(D18/C18,0) -> 0 | F18: ='Detalle metas'!AE2 -> 0 | H18: =IFERROR(G18/F18,0) -> 0 | I18: ='Detalle metas'!AF2 -> 24 | K18: =IFERROR(J18/I18,0) -> 0 | L18: ='Detalle metas'!AG2 -> 54 | N18: =IFERROR(M18/L18,0) -> 0 | O18: ='Detalle metas'!AH2 -> 54 | Q18: =IFERROR(P18/O18,0) -> 0 | R18: ='Detalle metas'!AI2 -> 54 | T18: =IFERROR(S18/R18,0) -> 0 | U18: ='Detalle metas'!AJ2 -> 54 | W18: =IFERROR(V18/U18,0) -> 0 | X18: ='Detalle metas'!AK2 -> 0 | Z18: =IFERROR(Y18/X18,0) -> 0
A19: Protección | B19: Sensibilizaciones VBG (80%) | C19: ='Detalle metas'!AD3 -> 960 | D19: =SUM(G19,J19,M19,P19,S19,V19,Y19) -> 0 | E19: =IFERROR(D19/C19,0) -> 0 | F19: ='Detalle metas'!AE3 -> 0 | H19: =IFERROR(G19/F19,0) -> 0 | I19: ='Detalle metas'!AF3 -> 96 | K19: =IFERROR(J19/I19,0) -> 0 | L19: ='Detalle metas'!AG3 -> 216 | N19: =IFERROR(M19/L19,0) -> 0 | O19: ='Detalle metas'!AH3 -> 216 | Q19: =IFERROR(P19/O19,0) -> 0 | R19: ='Detalle metas'!AI3 -> 216 | T19: =IFERROR(S19/R19,0) -> 0 | U19: ='Detalle metas'!AJ3 -> 216 | W19: =IFERROR(V19/U19,0) -> 0 | X19: ='Detalle metas'!AK3 -> 0 | Z19: =IFERROR(Y19/X19,0) -> 0
A20: Protección | B20: Gestión de Casos | C20: ='Detalle metas'!AD4 -> 96 | D20: =SUM(G20,J20,M20,P20,S20,V20,Y20) -> 0 | E20: =IFERROR(D20/C20,0) -> 0 | F20: ='Detalle metas'!AE4 -> 0 | H20: =IFERROR(G20/F20,0) -> 0 | I20: ='Detalle metas'!AF4 -> 16 | K20: =IFERROR(J20/I20,0) -> 0 | L20: ='Detalle metas'!AG4 -> 20 | N20: =IFERROR(M20/L20,0) -> 0 | O20: ='Detalle metas'!AH4 -> 20 | Q20: =IFERROR(P20/O20,0) -> 0 | R20: ='Detalle metas'!AI4 -> 20 | T20: =IFERROR(S20/R20,0) -> 0 | U20: ='Detalle metas'!AJ4 -> 20 | W20: =IFERROR(V20/U20,0) -> 0 | X20: ='Detalle metas'!AK4 -> 0 | Z20: =IFERROR(Y20/X20,0) -> 0
A21: Protección | B21: Cash VBG | C21: ='Detalle metas'!AD5 -> 29 | D21: =SUM(G21,J21,M21,P21,S21,V21,Y21) -> 0 | E21: =IFERROR(D21/C21,0) -> 0 | F21: ='Detalle metas'!AE5 -> 0 | H21: =IFERROR(G21/F21,0) -> 0 | I21: ='Detalle metas'!AF5 -> 3 | K21: =IFERROR(J21/I21,0) -> 0 | L21: ='Detalle metas'!AG5 -> 7 | N21: =IFERROR(M21/L21,0) -> 0 | O21: ='Detalle metas'!AH5 -> 7 | Q21: =IFERROR(P21/O21,0) -> 0 | R21: ='Detalle metas'!AI5 -> 7 | T21: =IFERROR(S21/R21,0) -> 0 | U21: ='Detalle metas'!AJ5 -> 5 | W21: =IFERROR(V21/U21,0) -> 0 | X21: ='Detalle metas'!AK5 -> 0 | Z21: =IFERROR(Y21/X21,0) -> 0
A22: Protección | B22: Kits - CARE Package- (meta hogar) | C22: ='Detalle metas'!AD6 -> 300 | D22: =SUM(G22,J22,M22,P22,S22,V22,Y22) -> 0 | E22: =IFERROR(D22/C22,0) -> 0 | F22: ='Detalle metas'!AE6 -> 0 | H22: =IFERROR(G22/F22,0) -> 0 | I22: ='Detalle metas'!AF6 -> 30 | K22: =IFERROR(J22/I22,0) -> 0 | L22: ='Detalle metas'!AG6 -> 60 | N22: =IFERROR(M22/L22,0) -> 0 | O22: ='Detalle metas'!AH6 -> 75 | Q22: =IFERROR(P22/O22,0) -> 0 | R22: ='Detalle metas'!AI6 -> 75 | T22: =IFERROR(S22/R22,0) -> 0 | U22: ='Detalle metas'!AJ6 -> 60 | W22: =IFERROR(V22/U22,0) -> 0 | X22: ='Detalle metas'!AK6 -> 0 | Z22: =IFERROR(Y22/X22,0) -> 0
A23: Protección | B23: Kits - CARE Package- (meta personas) | C23: ='Detalle metas'!AD7 -> 1200 | D23: =SUM(G23,J23,M23,P23,S23,V23,Y23) -> 0 | E23: =IFERROR(D23/C23,0) -> 0 | F23: ='Detalle metas'!AE7 -> 0 | H23: =IFERROR(G23/F23,0) -> 0 | I23: ='Detalle metas'!AF7 -> 120 | J23: =J22*4 -> 0 | K23: =IFERROR(J23/I23,0) -> 0 | L23: ='Detalle metas'!AG7 -> 240 | M23: =M22*4 -> 0 | N23: =IFERROR(M23/L23,0) -> 0 | O23: ='Detalle metas'!AH7 -> 300 | P23: =P22*4 -> 0 | Q23: =IFERROR(P23/O23,0) -> 0 | R23: ='Detalle metas'!AI7 -> 300 | S23: =S22*4 -> 0 | T23: =IFERROR(S23/R23,0) -> 0 | U23: ='Detalle metas'!AJ7 -> 240 | V23: =V22*4 -> 0 | W23: =IFERROR(V23/U23,0) -> 0 | X23: ='Detalle metas'!AK7 -> 0 | Y23: =Y22*4 -> 0 | Z23: =IFERROR(Y23/X23,0) -> 0
A24: Protección | B24: Espacios seguros mejorados | C24: ='Detalle metas'!AD8 -> 1 | D24: =SUM(G24,J24,M24,P24,S24,V24,Y24) -> 0 | E24: =IFERROR(D24/C24,0) -> 0 | F24: ='Detalle metas'!AE8 -> 0 | H24: =IFERROR(G24/F24,0) -> 0 | I24: ='Detalle metas'!AF8 -> 0 | K24: =IFERROR(J24/I24,0) -> 0 | L24: ='Detalle metas'!AG8 -> 0 | N24: =IFERROR(M24/L24,0) -> 0 | O24: ='Detalle metas'!AH8 -> 1 | Q24: =IFERROR(P24/O24,0) -> 0 | R24: ='Detalle metas'!AI8 -> 0 | T24: =IFERROR(S24/R24,0) -> 0 | U24: ='Detalle metas'!AJ8 -> 0 | W24: =IFERROR(V24/U24,0) -> 0 | X24: ='Detalle metas'!AK8 -> 0 | Z24: =IFERROR(Y24/X24,0) -> 0
A25: Protección | B25: Espacios seguros participantes | C25: ='Detalle metas'!AD9 -> 900 | D25: =SUM(G25,J25,M25,P25,S25,V25,Y25) -> 0 | E25: =IFERROR(D25/C25,0) -> 0 | F25: ='Detalle metas'!AE9 -> 0 | H25: =IFERROR(G25/F25,0) -> 0 | I25: ='Detalle metas'!AF9 -> 0 | K25: =IFERROR(J25/I25,0) -> 0 | L25: ='Detalle metas'!AG9 -> 0 | N25: =IFERROR(M25/L25,0) -> 0 | O25: ='Detalle metas'!AH9 -> 180 | Q25: =IFERROR(P25/O25,0) -> 0 | R25: ='Detalle metas'!AI9 -> 360 | T25: =IFERROR(S25/R25,0) -> 0 | U25: ='Detalle metas'!AJ9 -> 360 | W25: =IFERROR(V25/U25,0) -> 0 | X25: ='Detalle metas'!AK9 -> 0 | Z25: =IFERROR(Y25/X25,0) -> 0
A27: MUNICIPIO: CONVENCIÓN
A28: Sector | B28: Actividad | C28: TOTAL | F28: May | I28: Jun | L28: Jul | O28: Ago | R28: Sep | U28: Oct | X28: Nov
C29: Meta | D29: Avance | E29: % Av | F29: Meta | G29: Avance | H29: % Av | I29: Meta | J29: Avance | K29: % Av | L29: Meta | M29: Avance | N29: % Av | O29: Meta | P29: Avance | Q29: % Av | R29: Meta | S29: Avance | T29: % Av | U29: Meta | V29: Avance | W29: % Av | X29: Meta | Y29: Avance | Z29: % Av
A30: Protección | B30: Sensibilizaciones general (10%) | C30: ='Detalle metas'!AL2 -> 160 | D30: =SUM(G30,J30,M30,P30,S30,V30,Y30) -> 0 | E30: =IFERROR(D30/C30,0) -> 0 | F30: ='Detalle metas'!AM2 -> 0 | H30: =IFERROR(G30/F30,0) -> 0 | I30: ='Detalle metas'!AN2 -> 16 | K30: =IFERROR(J30/I30,0) -> 0 | L30: ='Detalle metas'!AO2 -> 36 | N30: =IFERROR(M30/L30,0) -> 0 | O30: ='Detalle metas'!AP2 -> 36 | Q30: =IFERROR(P30/O30,0) -> 0 | R30: ='Detalle metas'!AQ2 -> 36 | T30: =IFERROR(S30/R30,0) -> 0 | U30: ='Detalle metas'!AR2 -> 36 | W30: =IFERROR(V30/U30,0) -> 0 | X30: ='Detalle metas'!AS2 -> 0 | Z30: =IFERROR(Y30/X30,0) -> 0
A31: Protección | B31: Sensibilizaciones VBG (80%) | C31: ='Detalle metas'!AL3 -> 640 | D31: =SUM(G31,J31,M31,P31,S31,V31,Y31) -> 0 | E31: =IFERROR(D31/C31,0) -> 0 | F31: ='Detalle metas'!AM3 -> 0 | H31: =IFERROR(G31/F31,0) -> 0 | I31: ='Detalle metas'!AN3 -> 64 | K31: =IFERROR(J31/I31,0) -> 0 | L31: ='Detalle metas'!AO3 -> 144 | N31: =IFERROR(M31/L31,0) -> 0 | O31: ='Detalle metas'!AP3 -> 144 | Q31: =IFERROR(P31/O31,0) -> 0 | R31: ='Detalle metas'!AQ3 -> 144 | T31: =IFERROR(S31/R31,0) -> 0 | U31: ='Detalle metas'!AR3 -> 144 | W31: =IFERROR(V31/U31,0) -> 0 | X31: ='Detalle metas'!AS3 -> 0 | Z31: =IFERROR(Y31/X31,0) -> 0
A32: Protección | B32: Gestión de Casos | C32: ='Detalle metas'!AL4 -> 96 | D32: =SUM(G32,J32,M32,P32,S32,V32,Y32) -> 0 | E32: =IFERROR(D32/C32,0) -> 0 | F32: ='Detalle metas'!AM4 -> 0 | H32: =IFERROR(G32/F32,0) -> 0 | I32: ='Detalle metas'!AN4 -> 16 | K32: =IFERROR(J32/I32,0) -> 0 | L32: ='Detalle metas'!AO4 -> 20 | N32: =IFERROR(M32/L32,0) -> 0 | O32: ='Detalle metas'!AP4 -> 20 | Q32: =IFERROR(P32/O32,0) -> 0 | R32: ='Detalle metas'!AQ4 -> 20 | T32: =IFERROR(S32/R32,0) -> 0 | U32: ='Detalle metas'!AR4 -> 20 | W32: =IFERROR(V32/U32,0) -> 0 | X32: ='Detalle metas'!AS4 -> 0 | Z32: =IFERROR(Y32/X32,0) -> 0
A33: Protección | B33: Cash VBG | C33: ='Detalle metas'!AL5 -> 29 | D33: =SUM(G33,J33,M33,P33,S33,V33,Y33) -> 0 | E33: =IFERROR(D33/C33,0) -> 0 | F33: ='Detalle metas'!AM5 -> 0 | H33: =IFERROR(G33/F33,0) -> 0 | I33: ='Detalle metas'!AN5 -> 3 | K33: =IFERROR(J33/I33,0) -> 0 | L33: ='Detalle metas'!AO5 -> 7 | N33: =IFERROR(M33/L33,0) -> 0 | O33: ='Detalle metas'!AP5 -> 7 | Q33: =IFERROR(P33/O33,0) -> 0 | R33: ='Detalle metas'!AQ5 -> 7 | T33: =IFERROR(S33/R33,0) -> 0 | U33: ='Detalle metas'!AR5 -> 5 | W33: =IFERROR(V33/U33,0) -> 0 | X33: ='Detalle metas'!AS5 -> 0 | Z33: =IFERROR(Y33/X33,0) -> 0
A34: Protección | B34: Kits - CARE Package- (meta hogar) | C34: ='Detalle metas'!AL6 -> 300 | D34: =SUM(G34,J34,M34,P34,S34,V34,Y34) -> 0 | E34: =IFERROR(D34/C34,0) -> 0 | F34: ='Detalle metas'!AM6 -> 0 | H34: =IFERROR(G34/F34,0) -> 0 | I34: ='Detalle metas'!AN6 -> 30 | K34: =IFERROR(J34/I34,0) -> 0 | L34: ='Detalle metas'!AO6 -> 60 | N34: =IFERROR(M34/L34,0) -> 0 | O34: ='Detalle metas'!AP6 -> 75 | Q34: =IFERROR(P34/O34,0) -> 0 | R34: ='Detalle metas'!AQ6 -> 75 | T34: =IFERROR(S34/R34,0) -> 0 | U34: ='Detalle metas'!AR6 -> 60 | W34: =IFERROR(V34/U34,0) -> 0 | X34: ='Detalle metas'!AS6 -> 0 | Z34: =IFERROR(Y34/X34,0) -> 0
A35: Protección | B35: Kits - CARE Package- (meta personas) | C35: ='Detalle metas'!AL7 -> 1200 | D35: =SUM(G35,J35,M35,P35,S35,V35,Y35) -> 0 | E35: =IFERROR(D35/C35,0) -> 0 | F35: ='Detalle metas'!AM7 -> 0 | H35: =IFERROR(G35/F35,0) -> 0 | I35: ='Detalle metas'!AN7 -> 120 | J35: =J34*4 -> 0 | K35: =IFERROR(J35/I35,0) -> 0 | L35: ='Detalle metas'!AO7 -> 240 | M35: =M34*4 -> 0 | N35: =IFERROR(M35/L35,0) -> 0 | O35: ='Detalle metas'!AP7 -> 300 | P35: =P34*4 -> 0 | Q35: =IFERROR(P35/O35,0) -> 0 | R35: ='Detalle metas'!AQ7 -> 300 | S35: =S34*4 -> 0 | T35: =IFERROR(S35/R35,0) -> 0 | U35: ='Detalle metas'!AR7 -> 240 | V35: =V34*4 -> 0 | W35: =IFERROR(V35/U35,0) -> 0 | X35: ='Detalle metas'!AS7 -> 0 | Y35: =Y34*4 -> 0 | Z35: =IFERROR(Y35/X35,0) -> 0
A36: Protección | B36: Espacios seguros mejorados | C36: ='Detalle metas'!AL8 -> 1 | D36: =SUM(G36,J36,M36,P36,S36,V36,Y36) -> 0 | E36: =IFERROR(D36/C36,0) -> 0 | F36: ='Detalle metas'!AM8 -> 0 | H36: =IFERROR(G36/F36,0) -> 0 | I36: ='Detalle metas'!AN8 -> 0 | K36: =IFERROR(J36/I36,0) -> 0 | L36: ='Detalle metas'!AO8 -> 0 | N36: =IFERROR(M36/L36,0) -> 0 | O36: ='Detalle metas'!AP8 -> 1 | Q36: =IFERROR(P36/O36,0) -> 0 | R36: ='Detalle metas'!AQ8 -> 0 | T36: =IFERROR(S36/R36,0) -> 0 | U36: ='Detalle metas'!AR8 -> 0 | W36: =IFERROR(V36/U36,0) -> 0 | X36: ='Detalle metas'!AS8 -> 0 | Z36: =IFERROR(Y36/X36,0) -> 0
A37: Protección | B37: Espacios seguros participantes | C37: ='Detalle metas'!AL9 -> 450 | D37: =SUM(G37,J37,M37,P37,S37,V37,Y37) -> 0 | E37: =IFERROR(D37/C37,0) -> 0 | F37: ='Detalle metas'!AM9 -> 0 | H37: =IFERROR(G37/F37,0) -> 0 | I37: ='Detalle metas'!AN9 -> 0 | K37: =IFERROR(J37/I37,0) -> 0 | L37: ='Detalle metas'!AO9 -> 0 | N37: =IFERROR(M37/L37,0) -> 0 | O37: ='Detalle metas'!AP9 -> 90 | Q37: =IFERROR(P37/O37,0) -> 0 | R37: ='Detalle metas'!AQ9 -> 180 | T37: =IFERROR(S37/R37,0) -> 0 | U37: ='Detalle metas'!AR9 -> 180 | W37: =IFERROR(V37/U37,0) -> 0 | X37: ='Detalle metas'!AS9 -> 0 | Z37: =IFERROR(Y37/X37,0) -> 0
A39: MUNICIPIO: TEORAMA
A40: Sector | B40: Actividad | C40: TOTAL | F40: May | I40: Jun | L40: Jul | O40: Ago | R40: Sep | U40: Oct | X40: Nov
C41: Meta | D41: Avance | E41: % Av | F41: Meta | G41: Avance | H41: % Av | I41: Meta | J41: Avance | K41: % Av | L41: Meta | M41: Avance | N41: % Av | O41: Meta | P41: Avance | Q41: % Av | R41: Meta | S41: Avance | T41: % Av | U41: Meta | V41: Avance | W41: % Av | X41: Meta | Y41: Avance | Z41: % Av
